<?xml version="1.0" ?>

<robot name="double_pendulum">

	<material name="material_red_custom">
		<color rgba="0.6 0.1 0.1 1.0" />
	</material>
	<material name="material_green_custom">
		<color rgba="0.1 0.3 0.1 1.0" />
	</material>
	<material name="material_blue">
		<color rgba="0.0 0.0 0.6 1.0" />
	</material>

	<link name="base_link">
		<inertial>
			<origin xyz="0.0 0.0 0.0" rpy="0 0 0" />
			<mass value="1" />
			<inertia ixx="0.1" iyy="0.1" izz="0.1" ixy="0" ixz="0" iyz="0" />
		</inertial>
		<visual>
			<origin xyz="0.0 0.0 0.025" rpy="0 0 0" />
			<geometry>
				<cylinder radius="0.25" length="0.05"/>
			</geometry>
			<material name="material_red_custom" />
		</visual>
	</link>
	<link name="link0">
		<inertial>
			<origin xyz="0.0 0.0 -1.0" rpy="0 0 0" />
			<mass value="1" />
			<inertia ixx="0.1" iyy="0.1" izz="0.1" ixy="0" ixz="0" iyz="0" />
		</inertial>
		<visual>
			<origin xyz="0.0 0.0 -1.0" rpy="0 0 0" />
			<geometry>
				<sphere radius="0.1" />
			</geometry>
		</visual>
		<visual>
			<origin xyz="0.0 0.0 -0.5" rpy="0 0 0" />
			<geometry>
				<cylinder radius="0.05" length="1.0" />
			</geometry>
			<material name="material_green_custom" />
		</visual>
	</link>
	<link name="link1">
		<inertial>
			<origin xyz="0.0 0.0 -1.0" rpy="0 0 0" />
			<mass value="1" />
			<inertia ixx="0.1" iyy="0.1" izz="0.1" ixy="0" ixz="0" iyz="0" />
		</inertial>
		<visual>
			<origin xyz="0.0 0.0 -1.0" rpy="0 0 0" />
			<geometry>
				<sphere radius="0.1" />
			</geometry>
			<material name="material_blue" />
		</visual>
		<visual>
			<origin xyz="0.0 0.0 -0.5" rpy="0 0 0" />
			<geometry>
				<cylinder radius="0.05" length="1.0" />
			</geometry>
			<material name="material_green_custom" />
		</visual>
	</link>

	<joint name="j0" type="revolute">
		<parent link="base_link" />
		<child link="link0" />
		<origin xyz="0.000000 0.000000 0.000000" rpy="-0.000000 0.000000 -0.000000" />
		<axis xyz="1 0 0" />
		<limit lower="-1.4" upper="1.4" effort="176" velocity="1.7104" />
		<calibration rising="0.5" />
	</joint>
	<joint name="j1" type="revolute">
		<parent link="link0" />
		<child link="link1" />
		<origin xyz="0.000000 0.000000 -1.000000" rpy="-0.000000 0.000000 -0.000000" />
		<axis xyz="1 0 0" />
		<limit lower="-2.5" upper="2.5" effort="176" velocity="1.7104" />
		<calibration rising="0.8" />
	</joint>

</robot>