<?xml version="1.0" ?>

<robot name="RBot_description">
    <link name="base_link">
        <inertial>
            <origin xyz="0.0 0.0 0.0" rpy="0 0 0" />
            <mass value="1" />
            <inertia ixx="0.1" iyy="0.1" izz="0.1" ixy="0" ixz="0" iyz="0" />
        </inertial>
        <visual>
            <origin xyz="0.0 0.0 0.0" rpy="0 0 0" />
            <geometry>
                <sphere radius="0.1" />
            </geometry>
            <material name="material_red">
                <color rgba="1.0 0.1 0.1 1.0" />
            </material>
        </visual>
        <collision>
            <origin xyz="0.0 0.0 0.0" rpy="0 0 0" />
            <geometry>
                <sphere radius="0.1" />
            </geometry>
        </collision>
    </link>
    <link name="link0">
        <inertial>
            <origin xyz="0.0 0.0 -0.5" rpy="0 0 0" />
            <mass value="0.5" />
            <inertia ixx="0.1" iyy="0.1" izz="0.1" ixy="0" ixz="0" iyz="0" />
        </inertial>
        <visual>
            <origin xyz="0.0 0.0 -0.5" rpy="0 0 0" />
            <geometry>
                <cylinder radius="0.07" length="1.0" />
            </geometry>
        </visual>
        <collision>
            <origin xyz="0.0 0.0 -0.4475" rpy="0 0 0" />
            <geometry>
                <cylinder radius="0.07" length="0.79" />
            </geometry>
        </collision>
    </link>
    <link name="eef">
        <inertial>
            <origin xyz="0.0 0.0 0.0" rpy="0 0 0" />
            <mass value="1" />
            <inertia ixx="0.1" iyy="0.1" izz="0.1" ixy="0" ixz="0" iyz="0" />
        </inertial>
        <visual>
            <origin xyz="0.0 0.0 0.0" rpy="0 0 0" />
            <geometry>
                <sphere radius="0.1" />
            </geometry>
            <material name="material_red">
                <color rgba="0.1 0.1 1.0 1.0" />
            </material>
        </visual>
        <collision>
            <origin xyz="0.0 0.0 0.0" rpy="0 0 0" />
            <geometry>
                <sphere radius="0.1" />
            </geometry>
        </collision>
    </link>
    
    <joint name="j0" type="revolute">
        <parent link="base_link" />
        <child link="link0" />
        <origin xyz="0.000000 0.000000 0.000000" rpy="-0.000000 0.000000 -0.000000" />
        <axis xyz="1 0 0" />
        <calibration rising="2.0" />
        <limit lower="-2.967" upper="2.967" effort="176" velocity="1.7104" />
    </joint>
	<joint name='jfixed' type='fixed'>
		<parent link='link0'/>
		<child link='eef'/>
		<origin xyz='0.0 0.0 -1.0' rpy='0 0 0'/>
	</joint>
    
</robot>



