<?xml version="1.0" ?>
<robot name="kuka_iiwa">
    <link name="base_link">
        <inertial>
            <origin xyz="0 0 0.14" rpy="0 -0 0" />
            <mass value="4" />
            <inertia ixx="0.4" iyy="0.4" izz="0.4" ixy="0" ixz="0" iyz="0" />
        </inertial>
        <visual>
            <origin xyz="0 0 0" rpy="0 -0 0" />
            <geometry>
                <mesh filename="meshes/base.obj" scale="1 1 1" />
            </geometry>
        </visual>
        <!-- <collision>
            <origin xyz="0 0 0" rpy="0 -0 0" />
            <geometry>
                <mesh filename="meshes/base.obj" scale="1 1 1" />
            </geometry>
        </collision> -->
    </link>
    <link name="link0">
        <inertial>
            <origin xyz="0 0 0.14" rpy="0 -0 0" />
            <mass value="4" />
            <inertia ixx="0.4" iyy="0.4" izz="0.4" ixy="0" ixz="0" iyz="0" />
        </inertial>
        <visual>
            <origin xyz="0 0 0" rpy="0 -0 0" />
            <geometry>
                <mesh filename="meshes/link0.obj" scale="1 1 1" />
            </geometry>
        </visual>
        <!-- <collision>
            <origin xyz="0 0 0" rpy="0 -0 0" />
            <geometry>
                <mesh filename="meshes/link0.obj" scale="1 1 1" />
            </geometry>
        </collision> -->
    </link>
    <link name="link1">
        <inertial>
            <origin xyz="0 0 0.14" rpy="0 -0 0" />
            <mass value="4" />
            <inertia ixx="0.4" iyy="0.4" izz="0.4" ixy="0" ixz="0" iyz="0" />
        </inertial>
        <visual>
            <origin xyz="0 0 0" rpy="0 -0 0" />
            <geometry>
                <mesh filename="meshes/link1.obj" scale="1 1 1" />
            </geometry>
        </visual>
        <!-- <collision>
            <origin xyz="0 0 0" rpy="0 -0 0" />
            <geometry>
                <mesh filename="meshes/link1.obj" scale="1 1 1" />
            </geometry>
        </collision> -->
    </link>
    <link name="link2">
        <inertial>
            <origin xyz="0 0 0.14" rpy="0 -0 0" />
            <mass value="4" />
            <inertia ixx="0.4" iyy="0.4" izz="0.4" ixy="0" ixz="0" iyz="0" />
        </inertial>
        <visual>
            <origin xyz="0 0 0" rpy="0 -0 0" />
            <geometry>
                <mesh filename="meshes/link2.obj" scale="1 1 1" />
            </geometry>
        </visual>
        <!-- <collision>
            <origin xyz="0 0 0" rpy="0 -0 0" />
            <geometry>
                <mesh filename="meshes/link2.obj" scale="1 1 1" />
            </geometry>
        </collision> -->
    </link>
    <link name="link3">
        <inertial>
            <origin xyz="0 0 0.14" rpy="0 0 0" />
            <mass value="4" />
            <inertia ixx="0.4" iyy="0.4" izz="0.4" ixy="0" ixz="0" iyz="0" />
        </inertial>
        <visual>
            <origin xyz="0 0 0" rpy="0 0 3.1415926535897" />
            <geometry>
                <mesh filename="meshes/link3.obj" scale="1 1 1" />
            </geometry>
        </visual>
        <!-- <collision>
            <origin xyz="0 0 0" rpy="0 -0 0" />
            <geometry>
                <mesh filename="meshes/link3.obj" scale="1 1 1" />
            </geometry>
        </collision> -->
    </link>
    <link name="link4">
        <inertial>
            <origin xyz="0 0 0.14" rpy="0 0 0" />
            <mass value="3" />
            <inertia ixx="0.3" iyy="0.3" izz="0.3" ixy="0" ixz="0" iyz="0" />
        </inertial>
        <visual>
            <origin xyz="0 0 0" rpy="0 0 0" />
            <geometry>
                <mesh filename="meshes/link4.obj" scale="1 1 1" />
            </geometry>
        </visual>
        <!-- <collision>
            <origin xyz="0 0 0" rpy="0 -0 0" />
            <geometry>
                <mesh filename="meshes/link4.obj" scale="1 1 1" />
            </geometry>
        </collision> -->
    </link>
    <link name="link5">
        <inertial>
            <origin xyz="0 0 0.14" rpy="0 0 0" />
            <mass value="2" />
            <inertia ixx="0.2" iyy="0.2" izz="0.2" ixy="0" ixz="0" iyz="0" />
        </inertial>
        <visual>
            <origin xyz="0 -0.06 0" rpy="0 0 0" />
            <geometry>
                <mesh filename="meshes/link5.obj" scale="1 1 1" />
            </geometry>
        </visual>
        <!-- <collision>
            <origin xyz="0 -0.06 0" rpy="0 -0 0" />
            <geometry>
                <mesh filename="meshes/link5.obj" scale="1 1 1" />
            </geometry>
        </collision> -->
    </link>
    <link name="link6">
        <inertial>
            <origin xyz="0 0 0.03" rpy="0 0 0" />
            <mass value="1" />
            <inertia ixx="0.1" iyy="0.1" izz="0.1" ixy="0" ixz="0" iyz="0" />
        </inertial>
        <visual>
            <origin xyz="0 0 0" rpy="0 0 0" />
            <geometry>
                <mesh filename="meshes/link6.obj" scale="1 1 1" />
            </geometry>
        </visual>
        <!-- <collision>
            <origin xyz="0 0 0" rpy="0 0 0" />
            <geometry>
                <mesh filename="meshes/link6.obj" scale="1 1 1" />
            </geometry>
        </collision> -->
    </link>

    <link name="end-effector">
        <inertial>
            <origin xyz="0 0 0" rpy="0 0 0" />
            <mass value="1" />
            <inertia ixx="0.1" iyy="0.1" izz="0.1" ixy="0" ixz="0" iyz="0" />
        </inertial>
        <visual>
            <origin xyz="0 0 0" rpy="0 0 0" />
            <geometry>
                <box size="0.07 0.07 0.07" />
            </geometry>
            <material name="material_red">
                <color rgba="0.6 0.1 0.1 1.0" />
            </material>
        </visual>
        <collision>
            <origin xyz="0 0 0" rpy="0 0 0" />
            <geometry>
                <box size="0.07 0.07 0.07" />
            </geometry>
        </collision>
    </link>

    <joint name="j0" type="revolute">
        <parent link="base_link" />
        <child link="link0" />
        <origin xyz="0.000000 0.000000 0.155767" rpy="0.000000 0.000000 0.000000" />
        <axis xyz="0 0 1" />
        <limit lower="-2.967" upper="2.967" effort="176" velocity="1.7104" />
    </joint>
    <joint name="j1" type="revolute">
        <parent link="link0" />
        <child link="link1" />
        <origin xyz="0.000000 0.000000 0.182500" rpy="0.000000 0.000000 0.000000" />
        <axis xyz="0 1 0" />
        <limit lower="-2.0944" upper="2.0944" effort="176" velocity="1.7104" />
        <calibration falling="30"/>
    </joint>
    <joint name="j2" type="revolute">
        <parent link="link1" />
        <child link="link2" />
        <origin xyz="0.000000 0.000000 0.185000" rpy="0.000000 0.000000 0.000000" />
        <axis xyz="0 0 1" />
        <limit lower="-2.967" upper="2.967" effort="110" velocity="1.7453" />
    </joint>
    <joint name="j3" type="revolute">
        <parent link="link2" />
        <child link="link3" />
        <origin xyz="0.000000 0.000000 0.217000" rpy="0.000000 0.000000 3.1415926535897" />
        <axis xyz="0 1 0" />
        <limit lower="-2.0944" upper="2.0944" effort="110" velocity="2.2689" />
        <calibration falling="-60"/>
    </joint>
    <joint name="j4" type="revolute">
        <parent link="link3" />
        <child link="link4" />
        <origin xyz="0.000000 0.000000 0.186000" rpy="0.000000 0.000000 -3.1415926535897" />
        <axis xyz="0 0 1" />
        <limit lower="-2.967" upper="2.967" effort="110" velocity="2.4434" />
    </joint>
    <joint name="j5" type="revolute">
        <parent link="link4" />
        <child link="link5" />
        <origin xyz="0.000000 0.000000 0.217003" rpy="0.000000 0.000000 0.000000" />
        <axis xyz="0 1 0" />
        <limit lower="-2.0944" upper="2.0944" effort="40" velocity="3.1416" />
        <calibration falling="90"/>
    </joint>
    <joint name="j6" type="revolute">
        <parent link="link5" />
        <child link="link6" />
        <origin xyz="0.000000 0.000000 0.081000" rpy="0.000000 0.000000 0.000000" />
        <axis xyz="0 0 1" />
        <limit lower="-3.0543" upper="3.0543" effort="40" velocity="3.1416" />
    </joint>
    <joint name="jee" type="fixed">
        <parent link="link6" />
        <child link="end-effector" />
        <origin xyz="0.000000 0.000000 0.05" rpy="0.000000 0.000000 0.000000" />
    </joint>
</robot>
