<?xml version="1.0" ?>
<!--simple pbot-->

<robot name="linkage">
    <link name="base_link">
        <inertial>
            <origin xyz="0.0 0.0 0.0" rpy="0 0 0" />
            <mass value="1" />
            <inertia ixx="0.1" iyy="0.1" izz="0.1" ixy="0" ixz="0" iyz="0" />
        </inertial>
<!--         <collision>
            <origin xyz="0.0 0.0 0.0" rpy="0 0 0" />
            <geometry>
                <sphere radius="0.15"/>
            </geometry>
        </collision> -->
        <visual>
            <origin xyz="0.0 0.0 0.0" rpy="0 0 0" />
            <geometry>
                <sphere radius="0.15"/>
            </geometry>
        </visual>
    </link>
    <link name="link0">
        <inertial>
            <origin xyz="1.0 0.0 0.0" rpy="0 0 0" />
            <mass value="1" />
            <inertia ixx="0.1" iyy="0.1" izz="0.1" ixy="0" ixz="0" iyz="0" />
        </inertial>
<!--         <collision>
            <origin xyz="1.0 0.0 0.0" rpy="0 0 0" />
            <geometry>
                <sphere radius="0.15" />
            </geometry>
        </collision> -->
        <visual>
            <origin xyz="0.0 0.0 0.0" rpy="0 1.57079632679 0" />
            <geometry>
                <cylinder radius="0.1" length="1.0" />
            </geometry>
        </visual>
        <visual>
            <origin xyz="1.0 0.0 0.0" rpy="0 -0.9553164380546082 0" />
            <geometry>
                <box size="0.30 0.30 0.30" />
            </geometry>
            <material name="material_red">
                <color rgba="0.8 0.1 0.1 1.0" />
            </material>
        </visual>
    </link>
    <link name="link1">
        <inertial>
            <origin xyz="1.0 0.0 0.0" rpy="0 0 0" />
            <mass value="1" />
            <inertia ixx="0.1" iyy="0.1" izz="0.1" ixy="0" ixz="0" iyz="0" />
        </inertial>
<!--         <collision>
            <origin xyz="1.0 0.0 0.0" rpy="0 0 0" />
            <geometry>
                <sphere radius="0.15" />
            </geometry>
        </collision> -->
        <visual>
            <origin xyz="0.0 0.0 0.0" rpy="0 1.57079632679 0" />
            <geometry>
                <cylinder radius="0.1" length="1.0" />
            </geometry>
        </visual>
        <visual>
            <origin xyz="1.0 0.0 0.0" rpy="0 0 0" />
            <geometry>
                <sphere radius="0.15" />
            </geometry>
            <material name="material_red">
                <color rgba="0.8 0.1 0.1 1.0" />
            </material>
        </visual>
    </link>
    <link name="link2">
        <inertial>
            <origin xyz="1.0 0.0 0.0" rpy="0 0 0" />
            <mass value="1" />
            <inertia ixx="0.1" iyy="0.1" izz="0.1" ixy="0" ixz="0" iyz="0" />
        </inertial>
<!--         <collision>
            <origin xyz="1.0 0.0 0.0" rpy="0 0 0" />
            <geometry>
                <sphere radius="0.15" />
            </geometry>
        </collision> -->
        <visual>
            <origin xyz="0.0 0.0 0.0" rpy="0 1.57079632679 0" />
            <geometry>
                <cylinder radius="0.1" length="1.0" />
            </geometry>
        </visual>
        <visual>
            <origin xyz="1.0 0.0 0.0" rpy="0 0 0" />
            <geometry>
                <sphere radius="0.15" />
            </geometry>
            <material name="material_blue">
                <color rgba="0.1 0.1 0.8 1.0" />
            </material>
        </visual>
    </link>
    
    <joint name="j0" type="revolute">
        <parent link="base_link" />
        <child link="link0" />
        <origin xyz="0.000000 0.000000 0.000000" rpy="-0.000000 0.000000 -0.000000" />
        <axis xyz="0 1 0" />
        <limit lower="-2.967" upper="2.967" effort="176" velocity="1.7104" />
    </joint>
    <joint name="j1" type="revolute">
        <parent link="base_link" />
        <child link="link1" />
        <origin xyz="0.000000 0.000000 0.000000" rpy="-0.000000 0.000000 2.0943951023" />
        <axis xyz="0 1 0" />
        <limit lower="-2.967" upper="2.967" effort="176" velocity="1.7104" />
    </joint>
    <joint name="j2" type="revolute">
        <parent link="base_link" />
        <child link="link2" />
        <origin xyz="0.000000 0.000000 0.000000" rpy="-0.000000 0.000000 -2.0943951023" />
        <axis xyz="0 1 0" />
        <limit lower="-2.967" upper="2.967" effort="176" velocity="1.7104" />
    </joint>
    
</robot>



